[INFO   ] Logger: Record log in /storage/emulated/0/python/免费影视(GUI)/.kivy/logs/kivy_25-05-11_33.txt
[INFO   ] Kivy: v2.2.1
[INFO   ] Kivy: Installed at "/data/user/0/ru.iiec.pydroid3/files/aarch64-linux-android/lib/python3.11/site-packages/kivy/__init__.py"
[INFO   ] Python: v3.11.4 (main, Sep 30 2023, 10:54:38) [GCC 11.4.0]
[INFO   ] Python: Interpreter at "/data/user/0/ru.iiec.pydroid3/files/aarch64-linux-android/bin/python3"
[INFO   ] Logger: Purge log fired. Processing...
[INFO   ] Logger: Purge finished!
[INFO   ] Factory: 190 symbols loaded
[INFO   ] Image: Providers: img_tex, img_dds, img_sdl2, img_pil (img_ffpyplayer ignored)
[INFO   ] Text: Provider: sdl2
[INFO   ] Window: Provider: sdl2
[INFO   ] GL: Using the "OpenGL ES 2" graphics system
[INFO   ] GL: Backend used <sdl2>
[INFO   ] GL: OpenGL version <b'OpenGL ES 3.2 V@415.0 (GIT@18b3f87, Ia11ce2d146, 1599237608) (Date:09/04/20)'>
[INFO   ] GL: OpenGL vendor <b'Qualcomm'>
[INFO   ] GL: OpenGL renderer <b'Adreno (TM) 615'>
[INFO   ] GL: OpenGL parsed version: 3, 2
[INFO   ] GL: Texture max size <16384>
[INFO   ] GL: Texture max units <16>
[INFO   ] Window: auto add sdl2 input provider
[INFO   ] Window: virtual keyboard not allowed, single mode, not docked
[INFO   ] Video: Provider: null(['video_ffmpeg', 'video_ffpyplayer'] ignored)
[INFO   ] GL: NPOT texture support is available
[WARNING] Base: Unknown <android> provider
[INFO   ] Base: Start application main loop
[DEBUG  ] Starting new HTTPS connection (1): ikan234.com:443
[DEBUG  ] https://ikan234.com:443 "GET /search/%E7%81%AB%E5%BD%B1%E5%BF%8D%E8%80%85----------2---.html HTTP/1.1" 200 None
[INFO   ] Loader: using a thread pool of 2 workers
[DEBUG  ] Starting new HTTPS connection (1): ikan234.com:443
[DEBUG  ] https://ikan234.com:443 "GET /search/%E7%81%AB%E5%BD%B1%E5%BF%8D%E8%80%85----------2---.html HTTP/1.1" 200 None
[DEBUG  ] Starting new HTTPS connection (1): ikan234.com:443
[DEBUG  ] https://ikan234.com:443 "GET /play/432-3-2.html HTTP/1.1" 200 None
[DEBUG  ] Starting new HTTPS connection (1): ikan234.com:443
[DEBUG  ] https://ikan234.com:443 "GET /play/432-3-2.html HTTP/1.1" 200 None
[DEBUG  ] Starting new HTTPS connection (1): ikan234.com:443
[DEBUG  ] https://ikan234.com:443 "GET /index.php/ajax/suggest?mid=1&wd=%E7%94%84%E5%AC%9B%E4%BC%A0&limit=10&timestamp=1743741123771 HTTP/1.1" 200 None
[DEBUG  ] Starting new HTTPS connection (1): ikan234.com:443
[DEBUG  ] https://ikan234.com:443 "GET /index.php/ajax/suggest?mid=1&wd=%E7%94%84%E5%AC%9B%E4%BC%A0&limit=10&timestamp=1743741123771 HTTP/1.1" 200 None
[DEBUG  ] Starting new HTTPS connection (1): ikan234.com:443
[DEBUG  ] https://ikan234.com:443 "GET /search/%E7%94%84%E5%AC%9B%E4%BC%A0----------2---.html HTTP/1.1" 200 None
[DEBUG  ] Starting new HTTPS connection (1): ikan234.com:443
[DEBUG  ] https://ikan234.com:443 "GET /search/%E7%94%84%E5%AC%9B%E4%BC%A0----------2---.html HTTP/1.1" 200 None
[DEBUG  ] Starting new HTTPS connection (1): ikan234.com:443
[DEBUG  ] https://ikan234.com:443 "GET /search/%E7%94%84%E5%AC%9B%E4%BC%A0----------2---.html HTTP/1.1" 200 None
[DEBUG  ] Starting new HTTPS connection (1): ikan234.com:443
[DEBUG  ] https://ikan234.com:443 "GET /search/%E7%86%8A%E5%87%BA%E6%B2%A1----------2---.html HTTP/1.1" 200 None
[DEBUG  ] Starting new HTTPS connection (1): ikan234.com:443
[DEBUG  ] https://ikan234.com:443 "GET /search/%E7%86%8A%E5%87%BA%E6%B2%A1----------2---.html HTTP/1.1" 200 None
[ERROR  ] Loader: Failed to load image <https://img.liangzipic.com/upload/vod/20220605-1/36d7b7b320bd3c27d25c7c34d28e7efa.jpg>
Traceback (most recent call last):
  File "/data/user/0/ru.iiec.pydroid3/files/aarch64-linux-android/lib/python3.11/urllib/request.py", line 1348, in do_open
    h.request(req.get_method(), req.selector, req.data, headers,
  File "/data/user/0/ru.iiec.pydroid3/files/aarch64-linux-android/lib/python3.11/http/client.py", line 1286, in request
    self._send_request(method, url, body, headers, encode_chunked)
  File "/data/user/0/ru.iiec.pydroid3/files/aarch64-linux-android/lib/python3.11/http/client.py", line 1332, in _send_request
    self.endheaders(body, encode_chunked=encode_chunked)
  File "/data/user/0/ru.iiec.pydroid3/files/aarch64-linux-android/lib/python3.11/http/client.py", line 1281, in endheaders
    self._send_output(message_body, encode_chunked=encode_chunked)
  File "/data/user/0/ru.iiec.pydroid3/files/aarch64-linux-android/lib/python3.11/http/client.py", line 1041, in _send_output
    self.send(msg)
  File "/data/user/0/ru.iiec.pydroid3/files/aarch64-linux-android/lib/python3.11/http/client.py", line 979, in send
    self.connect()
  File "/data/user/0/ru.iiec.pydroid3/files/aarch64-linux-android/lib/python3.11/http/client.py", line 1458, in connect
    self.sock = self._context.wrap_socket(self.sock,
                ^^^^^^^^^^^^^^^^^^^^^^^^^^^^^^^^^^^^
  File "/data/user/0/ru.iiec.pydroid3/files/aarch64-linux-android/lib/python3.11/ssl.py", line 517, in wrap_socket
    return self.sslsocket_class._create(
           ^^^^^^^^^^^^^^^^^^^^^^^^^^^^^
  File "/data/user/0/ru.iiec.pydroid3/files/aarch64-linux-android/lib/python3.11/ssl.py", line 1075, in _create
    self.do_handshake()
  File "/data/user/0/ru.iiec.pydroid3/files/aarch64-linux-android/lib/python3.11/ssl.py", line 1346, in do_handshake
    self._sslobj.do_handshake()
ConnectionResetError: [Errno 104] Connection reset by peer

During handling of the above exception, another exception occurred:

Traceback (most recent call last):
  File "/data/user/0/ru.iiec.pydroid3/files/aarch64-linux-android/lib/python3.11/site-packages/kivy/loader.py", line 342, in _load_urllib
    fd = urllib.request.urlopen(request, context=ssl_ctx)
         ^^^^^^^^^^^^^^^^^^^^^^^^^^^^^^^^^^^^^^^^^^^^^^^^
  File "/data/user/0/ru.iiec.pydroid3/files/aarch64-linux-android/lib/python3.11/urllib/request.py", line 216, in urlopen
    return opener.open(url, data, timeout)
           ^^^^^^^^^^^^^^^^^^^^^^^^^^^^^^^
  File "/data/user/0/ru.iiec.pydroid3/files/aarch64-linux-android/lib/python3.11/urllib/request.py", line 519, in open
    response = self._open(req, data)
               ^^^^^^^^^^^^^^^^^^^^^
  File "/data/user/0/ru.iiec.pydroid3/files/aarch64-linux-android/lib/python3.11/urllib/request.py", line 536, in _open
    result = self._call_chain(self.handle_open, protocol, protocol +
             ^^^^^^^^^^^^^^^^^^^^^^^^^^^^^^^^^^^^^^^^^^^^^^^^^^^^^^^
  File "/data/user/0/ru.iiec.pydroid3/files/aarch64-linux-android/lib/python3.11/urllib/request.py", line 496, in _call_chain
    result = func(*args)
             ^^^^^^^^^^^
  File "/data/user/0/ru.iiec.pydroid3/files/aarch64-linux-android/lib/python3.11/urllib/request.py", line 1391, in https_open
    return self.do_open(http.client.HTTPSConnection, req,
           ^^^^^^^^^^^^^^^^^^^^^^^^^^^^^^^^^^^^^^^^^^^^^^
  File "/data/user/0/ru.iiec.pydroid3/files/aarch64-linux-android/lib/python3.11/urllib/request.py", line 1351, in do_open
    raise URLError(err)
urllib.error.URLError: <urlopen error [Errno 104] Connection reset by peer>
[ERROR  ] Loader: Failed to load image <http://inews.gtimg.com/newsapp_ls/0/14138833507/0>
Traceback (most recent call last):
  File "/data/user/0/ru.iiec.pydroid3/files/aarch64-linux-android/lib/python3.11/site-packages/kivy/loader.py", line 342, in _load_urllib
    fd = urllib.request.urlopen(request, context=ssl_ctx)
         ^^^^^^^^^^^^^^^^^^^^^^^^^^^^^^^^^^^^^^^^^^^^^^^^
  File "/data/user/0/ru.iiec.pydroid3/files/aarch64-linux-android/lib/python3.11/urllib/request.py", line 216, in urlopen
    return opener.open(url, data, timeout)
           ^^^^^^^^^^^^^^^^^^^^^^^^^^^^^^^
  File "/data/user/0/ru.iiec.pydroid3/files/aarch64-linux-android/lib/python3.11/urllib/request.py", line 519, in open
    response = self._open(req, data)
               ^^^^^^^^^^^^^^^^^^^^^
  File "/data/user/0/ru.iiec.pydroid3/files/aarch64-linux-android/lib/python3.11/urllib/request.py", line 536, in _open
    result = self._call_chain(self.handle_open, protocol, protocol +
             ^^^^^^^^^^^^^^^^^^^^^^^^^^^^^^^^^^^^^^^^^^^^^^^^^^^^^^^
  File "/data/user/0/ru.iiec.pydroid3/files/aarch64-linux-android/lib/python3.11/urllib/request.py", line 496, in _call_chain
    result = func(*args)
             ^^^^^^^^^^^
  File "/data/user/0/ru.iiec.pydroid3/files/aarch64-linux-android/lib/python3.11/urllib/request.py", line 1377, in http_open
    return self.do_open(http.client.HTTPConnection, req)
           ^^^^^^^^^^^^^^^^^^^^^^^^^^^^^^^^^^^^^^^^^^^^^
  File "/data/user/0/ru.iiec.pydroid3/files/aarch64-linux-android/lib/python3.11/urllib/request.py", line 1352, in do_open
    r = h.getresponse()
        ^^^^^^^^^^^^^^^
  File "/data/user/0/ru.iiec.pydroid3/files/aarch64-linux-android/lib/python3.11/http/client.py", line 1378, in getresponse
    response.begin()
  File "/data/user/0/ru.iiec.pydroid3/files/aarch64-linux-android/lib/python3.11/http/client.py", line 318, in begin
    version, status, reason = self._read_status()
                              ^^^^^^^^^^^^^^^^^^^
  File "/data/user/0/ru.iiec.pydroid3/files/aarch64-linux-android/lib/python3.11/http/client.py", line 279, in _read_status
    line = str(self.fp.readline(_MAXLINE + 1), "iso-8859-1")
               ^^^^^^^^^^^^^^^^^^^^^^^^^^^^^^
  File "/data/user/0/ru.iiec.pydroid3/files/aarch64-linux-android/lib/python3.11/socket.py", line 706, in readinto
    return self._sock.recv_into(b)
           ^^^^^^^^^^^^^^^^^^^^^^^
ConnectionResetError: [Errno 104] Connection reset by peer
[ERROR  ] Loader: Failed to load image <https://img.liangzipic.com/upload/vod/20220430-1/a37483cbc8dddf5b62c982b1e095bea7.jpg>
Traceback (most recent call last):
  File "/data/user/0/ru.iiec.pydroid3/files/aarch64-linux-android/lib/python3.11/urllib/request.py", line 1348, in do_open
    h.request(req.get_method(), req.selector, req.data, headers,
  File "/data/user/0/ru.iiec.pydroid3/files/aarch64-linux-android/lib/python3.11/http/client.py", line 1286, in request
    self._send_request(method, url, body, headers, encode_chunked)
  File "/data/user/0/ru.iiec.pydroid3/files/aarch64-linux-android/lib/python3.11/http/client.py", line 1332, in _send_request
    self.endheaders(body, encode_chunked=encode_chunked)
  File "/data/user/0/ru.iiec.pydroid3/files/aarch64-linux-android/lib/python3.11/http/client.py", line 1281, in endheaders
    self._send_output(message_body, encode_chunked=encode_chunked)
  File "/data/user/0/ru.iiec.pydroid3/files/aarch64-linux-android/lib/python3.11/http/client.py", line 1041, in _send_output
    self.send(msg)
  File "/data/user/0/ru.iiec.pydroid3/files/aarch64-linux-android/lib/python3.11/http/client.py", line 979, in send
    self.connect()
  File "/data/user/0/ru.iiec.pydroid3/files/aarch64-linux-android/lib/python3.11/http/client.py", line 1458, in connect
    self.sock = self._context.wrap_socket(self.sock,
                ^^^^^^^^^^^^^^^^^^^^^^^^^^^^^^^^^^^^
  File "/data/user/0/ru.iiec.pydroid3/files/aarch64-linux-android/lib/python3.11/ssl.py", line 517, in wrap_socket
    return self.sslsocket_class._create(
           ^^^^^^^^^^^^^^^^^^^^^^^^^^^^^
  File "/data/user/0/ru.iiec.pydroid3/files/aarch64-linux-android/lib/python3.11/ssl.py", line 1075, in _create
    self.do_handshake()
  File "/data/user/0/ru.iiec.pydroid3/files/aarch64-linux-android/lib/python3.11/ssl.py", line 1346, in do_handshake
    self._sslobj.do_handshake()
ConnectionResetError: [Errno 104] Connection reset by peer

During handling of the above exception, another exception occurred:

Traceback (most recent call last):
  File "/data/user/0/ru.iiec.pydroid3/files/aarch64-linux-android/lib/python3.11/site-packages/kivy/loader.py", line 342, in _load_urllib
    fd = urllib.request.urlopen(request, context=ssl_ctx)
         ^^^^^^^^^^^^^^^^^^^^^^^^^^^^^^^^^^^^^^^^^^^^^^^^
  File "/data/user/0/ru.iiec.pydroid3/files/aarch64-linux-android/lib/python3.11/urllib/request.py", line 216, in urlopen
    return opener.open(url, data, timeout)
           ^^^^^^^^^^^^^^^^^^^^^^^^^^^^^^^
  File "/data/user/0/ru.iiec.pydroid3/files/aarch64-linux-android/lib/python3.11/urllib/request.py", line 519, in open
    response = self._open(req, data)
               ^^^^^^^^^^^^^^^^^^^^^
  File "/data/user/0/ru.iiec.pydroid3/files/aarch64-linux-android/lib/python3.11/urllib/request.py", line 536, in _open
    result = self._call_chain(self.handle_open, protocol, protocol +
             ^^^^^^^^^^^^^^^^^^^^^^^^^^^^^^^^^^^^^^^^^^^^^^^^^^^^^^^
  File "/data/user/0/ru.iiec.pydroid3/files/aarch64-linux-android/lib/python3.11/urllib/request.py", line 496, in _call_chain
    result = func(*args)
             ^^^^^^^^^^^
  File "/data/user/0/ru.iiec.pydroid3/files/aarch64-linux-android/lib/python3.11/urllib/request.py", line 1391, in https_open
    return self.do_open(http.client.HTTPSConnection, req,
           ^^^^^^^^^^^^^^^^^^^^^^^^^^^^^^^^^^^^^^^^^^^^^^
  File "/data/user/0/ru.iiec.pydroid3/files/aarch64-linux-android/lib/python3.11/urllib/request.py", line 1351, in do_open
    raise URLError(err)
urllib.error.URLError: <urlopen error [Errno 104] Connection reset by peer>
[INFO   ] Base: Leaving application in progress...
